Workbook
Name _Toc92795621: diag!$A$1

Sheet PAID
A1: Code in PAID | B1: Disease | C1: Men_0to14 | D1: Men_14to34 | E1: Men_35to54 | F1: Men_55to64 | G1: Men_65to74 | H1: Men_75 | I1: Women_0to14 | J1: Women_14to34 | K1: Women_35to54 | L1: Women_55to64 | M1: Women_65to74 | N1: Women_75 | O1: HC | P1: MED | Q1: GP | R1: Other
A2: DIS00 | B2: Total minus listed diseases | C2: 1.3920218 | D2: 1.8719944 | E2: 1.9425051 | F2: 0.9672011 | G2: 0.81530589 | H2: 0.657127 | I2: 1.3265233 | J2: 1.8428153 | K2: 2.0309049 | L2: 1.0352241 | M2: 0.94421794 | N2: 0.98415906 | O2: 0.4834729 | P2: 0.14541119 | Q2: 0.2337772 | R2: 0.13733871
A3: DIS01 | B3: HIV infection | C3: 0.0048541114 | D3: 0.09627321 | E3: 0.37700265 | F3: 0.22733422 | G3: 0.084137931 | H3: 0.023461538 | I3: 0.0048541114 | J3: 0.053395225 | K3: 0.2265252 | L3: 0.08494695 | M3: 0.027506631 | N3: 0.0097082228 | O3: 0.37256116 | P3: 0.48688993 | Q3: 0.10829997 | R3: 0.032248938
A4: DIS02 | B4: Active colorectal cancer | C4: 0 | D4: 0.0074792067 | E4: 0.082271273 | F4: 0.17629559 | G4: 0.32481126 | H4: 0.34511196 | I4: 0 | J4: 0.0074792067 | K4: 0.081202815 | L4: 0.13355726 | M4: 0.21262316 | N4: 0.30023672 | O4: 0.74102055 | P4: 0.053122047 | Q4: 0.16916757 | R4: 0.036689833
A5: DIS03 | B5: Follow-up for colorectal cancer | C5: 0 | D5: 0.00060356653 | E5: 0.0065386374 | F5: 0.017402835 | G5: 0.037421125 | H5: 0.051705533 | I5: 0 | J5: 0.00080475537 | K5: 0.0072427984 | L5: 0.015089163 | M5: 0.027663466 | N5: 0.055427526 | O5: 0.10384532 | P5: 0.75765962 | Q5: 0.13152733 | R5: 0.0069677306
A6: DIS04 | B6: Active lung cancer | C6: 0 | D6: 0.004592145 | E6: 0.12628399 | F6: 0.35589124 | G6: 0.56253776 | H6: 0.3926284 | I6: 0 | J6: 0.004592145 | K6: 0.10561934 | L6: 0.24108761 | M6: 0.2755287 | N6: 0.21353474 | O6: 0.66430479 | P6: 0.1830924 | Q6: 0.11193271 | R6: 0.040670096
A7: DIS05 | B7: Follow-up for lung cancer | C7: 0 | D7: 0.00017208413 | E7: 0.0032695985 | F7: 0.011357553 | G7: 0.0216826 | H7: 0.019445507 | I7: 0 | J7: 0.00034416826 | K7: 0.0032695985 | L7: 0.0082600382 | M7: 0.011185468 | N7: 0.0108413 | O7: 0.315433 | P7: 0.23143082 | Q7: 0.285582 | R7: 0.16755418
A8: DIS06 | B8: Active female breast cancer | C8: 0 | D8: 0 | E8: 0 | F8: 0 | G8: 0 | H8: 0 | I8: 0 | J8: 0.039711007 | K8: 0.76940076 | L8: 0.63909902 | M8: 0.78429239 | N8: 0.68501487 | O8: 0.50196834 | P8: 0.2056255 | Q8: 0.21594494 | R8: 0.076461215
A9: DIS07 | B9: Follow-up for female breast cancer | C9: 0 | D9: 0 | E9: 0 | F9: 0 | G9: 0 | H9: 0 | I9: 0 | J9: 0.0015322089 | K9: 0.081560658 | L9: 0.1238732 | M9: 0.17054664 | N9: 0.20236944 | O9: 0.27906376 | P9: 0.024646119 | Q9: 0.67987312 | R9: 0.016417004
A10: DIS08 | B10: Active prostate cancer | C10: 0 | D10: 0 | E10: 0.033038529 | F10: 0.21845884 | G10: 0.57985989 | H10: 0.70796848 | I10: 0 | J10: 0 | K10: 0 | L10: 0 | M10: 0 | N10: 0 | O10: 0.3328472 | P10: 0.36292126 | Q10: 0.2813475 | R10: 0.022884034
A11: DIS09 | B11: Follow-up for prostate cancer | C11: 0 | D11: 0.00030546624 | E11: 0.0061093248 | F11: 0.090418006 | G11: 0.34334405 | H11: 0.51012862 | I11: 0 | J11: 0 | K11: 0 | L11: 0 | M11: 0 | N11: 0 | O11: 0.12189225 | P11: 0.8080034 | Q11: 0.046952521 | R11: 0.023151831
A12: DIS10 | B12: Other active cancers | C12: 0.049643727 | D12: 0.14844448 | E12: 0.56700924 | F12: 0.83737287 | G12: 1.4146029 | H12: 1.9098234 | I12: 0.03942296 | J12: 0.21244595 | K12: 0.75560673 | L12: 0.74757613 | M12: 1.1157671 | N12: 1.7883909 | O12: 0.62013889 | P12: 0.22908801 | Q12: 0.11494551 | R12: 0.035827596
A13: DIS11 | B13: Follow-up for other cancers | C13: 0.0040382572 | D13: 0.014748418 | E13: 0.055262672 | F13: 0.073039782 | G13: 0.12672227 | H13: 0.18558425 | I13: 0.0032920575 | J13: 0.021552003 | K13: 0.084101095 | L13: 0.076990251 | M13: 0.11043755 | N13: 0.19423139 | O13: 0.11159517 | P13: 0.19521511 | Q13: 0.43675594 | R13: 0.25643377
... A58: DIS56 | B58: Other long-term diseases | C58: 0.097909624 | D58: 0.147097 | E58: 0.34349766 | F58: 0.35942832 | G58: 0.51629303 | H58: 0.58245761 | I58: 0.078606777 | J58: 0.17663268 | K58: 0.34024176 | L58: 0.32338084 | M58: 0.51047892 | N58: 0.82455718 | O58: 0.37535044 | P58: 0.20679324 | Q58: 0.26119527 | R58: 0.15666105

Sheet Полуфабрикат
E1: Total costs in billion attributed to sex/age groups | R1: Cost attributed to provider | W1: Cost attributed to provider
A2: Code in PAID | B2: Disease | C2: Total cost (in billion) | D2: Check | E2: Men_0to14 | F2: Men_14to34 | G2: Men_35to54 | H2: Men_55to64 | I2: Men_65to74 | J2: Men_75 | K2: Women_0to14 | L2: Women_14to34 | M2: Women_35to54 | N2: Women_55to64 | O2: Women_65to74 | P2: Women_75 | Q2: Equals 1? | R2: HC | S2: MED | T2: GP | U2: Other | V2: Equals 1? After standartization | W2: HC | X2: MED | Y2: GP | Z2: Other
A3: DIS00 | B3: Total minus listed diseases | C3: =Final!E61 -> 15.81 | D3: =C3=ROUND(SUM(E3:P3),2) -> TRUE | E3: =$C3*Final!F61 -> 1.3920218 | F3: =$C3*Final!G61 -> 1.8719944 | G3: =$C3*Final!H61 -> 1.9425051 | H3: =$C3*Final!I61 -> 0.9672011 | I3: =$C3*Final!J61 -> 0.81530589 | J3: =$C3*Final!K61 -> 0.657127 | K3: =$C3*Final!M61 -> 1.3265233 | L3: =$C3*Final!N61 -> 1.8428153 | M3: =$C3*Final!O61 -> 2.0309049 | N3: =$C3*Final!P61 -> 1.0352241 | O3: =$C3*Final!Q61 -> 0.94421794 | P3: =$C3*Final!R61 -> 0.98415906 | Q3: =SUM(R3:U3)=1 -> FALSE | R3: =Final!BJ59/Final!AX59 -> 0.4834729 | S3: =Final!BE59/Final!AX59 -> 0.14541119 | T3: =Final!AY59/Final!AX59 -> 0.2337772 | U3: =Final!BL59/Final!AX59 -> 0.13733871 | V3: =SUM(W3:Z3)=1 -> TRUE | W3: =R3/SUM($R3:$U3) -> 0.4834729 | X3: =S3/SUM($R3:$U3) -> 0.14541119 | Y3: =T3/SUM($R3:$U3) -> 0.2337772 | Z3: =U3/SUM($R3:$U3) -> 0.13733871
A4: DIS01 | B4: HIV infection | C4: =INDEX(Final!$E:$E, MATCH(Полуфабрикат!$B4,Final!$B:$B,0)) -> 1.22 | D4: =C4=ROUND(SUM(E4:P4),2) -> TRUE | E4: =$C4*INDEX(Final!F:F,MATCH(Полуфабрикат!$B4,Final!$B:$B,0))/INDEX(Final!$T:$T,MATCH(Полуфабрикат!$B4,Final!$B:$B,0)) -> 0.0048541114 | F4: =$C4*INDEX(Final!G:G,MATCH(Полуфабрикат!$B4,Final!$B:$B,0))/INDEX(Final!$T:$T,MATCH(Полуфабрикат!$B4,Final!$B:$B,0)) -> 0.09627321 | G4: =$C4*INDEX(Final!H:H,MATCH(Полуфабрикат!$B4,Final!$B:$B,0))/INDEX(Final!$T:$T,MATCH(Полуфабрикат!$B4,Final!$B:$B,0)) -> 0.37700265 | H4: =$C4*INDEX(Final!I:I,MATCH(Полуфабрикат!$B4,Final!$B:$B,0))/INDEX(Final!$T:$T,MATCH(Полуфабрикат!$B4,Final!$B:$B,0)) -> 0.22733422 | I4: =$C4*INDEX(Final!J:J,MATCH(Полуфабрикат!$B4,Final!$B:$B,0))/INDEX(Final!$T:$T,MATCH(Полуфабрикат!$B4,Final!$B:$B,0)) -> 0.084137931 | J4: =$C4*INDEX(Final!K:K,MATCH(Полуфабрикат!$B4,Final!$B:$B,0))/INDEX(Final!$T:$T,MATCH(Полуфабрикат!$B4,Final!$B:$B,0)) -> 0.023461538 | K4: =$C4*INDEX(Final!M:M,MATCH(Полуфабрикат!$B4,Final!$B:$B,0))/INDEX(Final!$T:$T,MATCH(Полуфабрикат!$B4,Final!$B:$B,0)) -> 0.0048541114 | L4: =$C4*INDEX(Final!N:N,MATCH(Полуфабрикат!$B4,Final!$B:$B,0))/INDEX(Final!$T:$T,MATCH(Полуфабрикат!$B4,Final!$B:$B,0)) -> 0.053395225 | M4: =$C4*INDEX(Final!O:O,MATCH(Полуфабрикат!$B4,Final!$B:$B,0))/INDEX(Final!$T:$T,MATCH(Полуфабрикат!$B4,Final!$B:$B,0)) -> 0.2265252 | N4: =$C4*INDEX(Final!P:P,MATCH(Полуфабрикат!$B4,Final!$B:$B,0))/INDEX(Final!$T:$T,MATCH(Полуфабрикат!$B4,Final!$B:$B,0)) -> 0.08494695 | O4: =$C4*INDEX(Final!Q:Q,MATCH(Полуфабрикат!$B4,Final!$B:$B,0))/INDEX(Final!$T:$T,MATCH(Полуфабрикат!$B4,Final!$B:$B,0)) -> 0.027506631 | P4: =$C4*INDEX(Final!R:R,MATCH(Полуфабрикат!$B4,Final!$B:$B,0))/INDEX(Final!$T:$T,MATCH(Полуфабрикат!$B4,Final!$B:$B,0)) -> 0.0097082228 | Q4: =SUM(R4:U4)=1 -> TRUE | R4: =INDEX(Final!$BJ:$BJ,MATCH(Полуфабрикат!$B4,Final!$B:$B,0))/INDEX(Final!$AX:$AX,MATCH(Полуфабрикат!$B4,Final!$B:$B,0)) -> 0.37256116 | S4: =INDEX(Final!$BE:$BE,MATCH(Полуфабрикат!$B4,Final!$B:$B,0))/INDEX(Final!$AX:$AX,MATCH(Полуфабрикат!$B4,Final!$B:$B,0)) -> 0.48688993 | T4: =INDEX(Final!$AY:$AY,MATCH(Полуфабрикат!$B4,Final!$B:$B,0))/INDEX(Final!$AX:$AX,MATCH(Полуфабрикат!$B4,Final!$B:$B,0)) -> 0.10829997 | U4: =INDEX(Final!$BL:$BL,MATCH(Полуфабрикат!$B4,Final!$B:$B,0))/INDEX(Final!$AX:$AX,MATCH(Полуфабрикат!$B4,Final!$B:$B,0)) -> 0.032248938 | V4: =SUM(W4:Z4)=1 -> TRUE | W4: =R4/SUM($R4:$U4) -> 0.37256116 | X4: =S4/SUM($R4:$U4) -> 0.48688993 | Y4: =T4/SUM($R4:$U4) -> 0.10829997 | Z4: =U4/SUM($R4:$U4) -> 0.032248938
A5: DIS02 | B5: Active colorectal cancer | C5: =INDEX(Final!$E:$E, MATCH(Полуфабрикат!$B5,Final!$B:$B,0)) -> 1.67 | D5: =C5=ROUND(SUM(E5:P5),2) -> TRUE | E5: =$C5*INDEX(Final!F:F,MATCH(Полуфабрикат!$B5,Final!$B:$B,0))/INDEX(Final!$T:$T,MATCH(Полуфабрикат!$B5,Final!$B:$B,0)) -> 0 | F5: =$C5*INDEX(Final!G:G,MATCH(Полуфабрикат!$B5,Final!$B:$B,0))/INDEX(Final!$T:$T,MATCH(Полуфабрикат!$B5,Final!$B:$B,0)) -> 0.0074792067 | G5: =$C5*INDEX(Final!H:H,MATCH(Полуфабрикат!$B5,Final!$B:$B,0))/INDEX(Final!$T:$T,MATCH(Полуфабрикат!$B5,Final!$B:$B,0)) -> 0.082271273 | H5: =$C5*INDEX(Final!I:I,MATCH(Полуфабрикат!$B5,Final!$B:$B,0))/INDEX(Final!$T:$T,MATCH(Полуфабрикат!$B5,Final!$B:$B,0)) -> 0.17629559 | I5: =$C5*INDEX(Final!J:J,MATCH(Полуфабрикат!$B5,Final!$B:$B,0))/INDEX(Final!$T:$T,MATCH(Полуфабрикат!$B5,Final!$B:$B,0)) -> 0.32481126 | J5: =$C5*INDEX(Final!K:K,MATCH(Полуфабрикат!$B5,Final!$B:$B,0))/INDEX(Final!$T:$T,MATCH(Полуфабрикат!$B5,Final!$B:$B,0)) -> 0.34511196 | K5: =$C5*INDEX(Final!M:M,MATCH(Полуфабрикат!$B5,Final!$B:$B,0))/INDEX(Final!$T:$T,MATCH(Полуфабрикат!$B5,Final!$B:$B,0)) -> 0 | L5: =$C5*INDEX(Final!N:N,MATCH(Полуфабрикат!$B5,Final!$B:$B,0))/INDEX(Final!$T:$T,MATCH(Полуфабрикат!$B5,Final!$B:$B,0)) -> 0.0074792067 | M5: =$C5*INDEX(Final!O:O,MATCH(Полуфабрикат!$B5,Final!$B:$B,0))/INDEX(Final!$T:$T,MATCH(Полуфабрикат!$B5,Final!$B:$B,0)) -> 0.081202815 | N5: =$C5*INDEX(Final!P:P,MATCH(Полуфабрикат!$B5,Final!$B:$B,0))/INDEX(Final!$T:$T,MATCH(Полуфабрикат!$B5,Final!$B:$B,0)) -> 0.13355726 | O5: =$C5*INDEX(Final!Q:Q,MATCH(Полуфабрикат!$B5,Final!$B:$B,0))/INDEX(Final!$T:$T,MATCH(Полуфабрикат!$B5,Final!$B:$B,0)) -> 0.21262316 | P5: =$C5*INDEX(Final!R:R,MATCH(Полуфабрикат!$B5,Final!$B:$B,0))/INDEX(Final!$T:$T,MATCH(Полуфабрикат!$B5,Final!$B:$B,0)) -> 0.30023672 | Q5: =SUM(R5:U5)=1 -> TRUE | R5: =INDEX(Final!$BJ:$BJ,MATCH(Полуфабрикат!$B5,Final!$B:$B,0))/INDEX(Final!$AX:$AX,MATCH(Полуфабрикат!$B5,Final!$B:$B,0)) -> 0.74102055 | S5: =INDEX(Final!$BE:$BE,MATCH(Полуфабрикат!$B5,Final!$B:$B,0))/INDEX(Final!$AX:$AX,MATCH(Полуфабрикат!$B5,Final!$B:$B,0)) -> 0.053122047 | T5: =INDEX(Final!$AY:$AY,MATCH(Полуфабрикат!$B5,Final!$B:$B,0))/INDEX(Final!$AX:$AX,MATCH(Полуфабрикат!$B5,Final!$B:$B,0)) -> 0.16916757 | U5: =INDEX(Final!$BL:$BL,MATCH(Полуфабрикат!$B5,Final!$B:$B,0))/INDEX(Final!$AX:$AX,MATCH(Полуфабрикат!$B5,Final!$B:$B,0)) -> 0.036689833 | V5: =SUM(W5:Z5)=1 -> TRUE | W5: =R5/SUM($R5:$U5) -> 0.74102055 | X5: =S5/SUM($R5:$U5) -> 0.053122047 | Y5: =T5/SUM($R5:$U5) -> 0.16916757 | Z5: =U5/SUM($R5:$U5) -> 0.036689833
A6: DIS03 | B6: Follow-up for colorectal cancer | C6: =INDEX(Final!$E:$E, MATCH(Полуфабрикат!$B6,Final!$B:$B,0)) -> 0.22 | D6: =C6=ROUND(SUM(E6:P6),2) -> TRUE | E6: =$C6*INDEX(Final!F:F,MATCH(Полуфабрикат!$B6,Final!$B:$B,0))/INDEX(Final!$T:$T,MATCH(Полуфабрикат!$B6,Final!$B:$B,0)) -> 0 | F6: =$C6*INDEX(Final!G:G,MATCH(Полуфабрикат!$B6,Final!$B:$B,0))/INDEX(Final!$T:$T,MATCH(Полуфабрикат!$B6,Final!$B:$B,0)) -> 0.00060356653 | G6: =$C6*INDEX(Final!H:H,MATCH(Полуфабрикат!$B6,Final!$B:$B,0))/INDEX(Final!$T:$T,MATCH(Полуфабрикат!$B6,Final!$B:$B,0)) -> 0.0065386374 | H6: =$C6*INDEX(Final!I:I,MATCH(Полуфабрикат!$B6,Final!$B:$B,0))/INDEX(Final!$T:$T,MATCH(Полуфабрикат!$B6,Final!$B:$B,0)) -> 0.017402835 | I6: =$C6*INDEX(Final!J:J,MATCH(Полуфабрикат!$B6,Final!$B:$B,0))/INDEX(Final!$T:$T,MATCH(Полуфабрикат!$B6,Final!$B:$B,0)) -> 0.037421125 | J6: =$C6*INDEX(Final!K:K,MATCH(Полуфабрикат!$B6,Final!$B:$B,0))/INDEX(Final!$T:$T,MATCH(Полуфабрикат!$B6,Final!$B:$B,0)) -> 0.051705533 | K6: =$C6*INDEX(Final!M:M,MATCH(Полуфабрикат!$B6,Final!$B:$B,0))/INDEX(Final!$T:$T,MATCH(Полуфабрикат!$B6,Final!$B:$B,0)) -> 0 | L6: =$C6*INDEX(Final!N:N,MATCH(Полуфабрикат!$B6,Final!$B:$B,0))/INDEX(Final!$T:$T,MATCH(Полуфабрикат!$B6,Final!$B:$B,0)) -> 0.00080475537 | M6: =$C6*INDEX(Final!O:O,MATCH(Полуфабрикат!$B6,Final!$B:$B,0))/INDEX(Final!$T:$T,MATCH(Полуфабрикат!$B6,Final!$B:$B,0)) -> 0.0072427984 | N6: =$C6*INDEX(Final!P:P,MATCH(Полуфабрикат!$B6,Final!$B:$B,0))/INDEX(Final!$T:$T,MATCH(Полуфабрикат!$B6,Final!$B:$B,0)) -> 0.015089163 | O6: =$C6*INDEX(Final!Q:Q,MATCH(Полуфабрикат!$B6,Final!$B:$B,0))/INDEX(Final!$T:$T,MATCH(Полуфабрикат!$B6,Final!$B:$B,0)) -> 0.027663466 | P6: =$C6*INDEX(Final!R:R,MATCH(Полуфабрикат!$B6,Final!$B:$B,0))/INDEX(Final!$T:$T,MATCH(Полуфабрикат!$B6,Final!$B:$B,0)) -> 0.055427526 | Q6: =SUM(R6:U6)=1 -> TRUE | R6: =INDEX(Final!$BJ:$BJ,MATCH(Полуфабрикат!$B6,Final!$B:$B,0))/INDEX(Final!$AX:$AX,MATCH(Полуфабрикат!$B6,Final!$B:$B,0)) -> 0.10384532 | S6: =INDEX(Final!$BE:$BE,MATCH(Полуфабрикат!$B6,Final!$B:$B,0))/INDEX(Final!$AX:$AX,MATCH(Полуфабрикат!$B6,Final!$B:$B,0)) -> 0.75765962 | T6: =INDEX(Final!$AY:$AY,MATCH(Полуфабрикат!$B6,Final!$B:$B,0))/INDEX(Final!$AX:$AX,MATCH(Полуфабрикат!$B6,Final!$B:$B,0)) -> 0.13152733 | U6: =INDEX(Final!$BL:$BL,MATCH(Полуфабрикат!$B6,Final!$B:$B,0))/INDEX(Final!$AX:$AX,MATCH(Полуфабрикат!$B6,Final!$B:$B,0)) -> 0.0069677306 | V6: =SUM(W6:Z6)=1 -> TRUE | W6: =R6/SUM($R6:$U6) -> 0.10384532 | X6: =S6/SUM($R6:$U6) -> 0.75765962 | Y6: =T6/SUM($R6:$U6) -> 0.13152733 | Z6: =U6/SUM($R6:$U6) -> 0.0069677306
A7: DIS04 | B7: Active lung cancer | C7: =INDEX(Final!$E:$E, MATCH(Полуфабрикат!$B7,Final!$B:$B,0)) -> 2.28 | D7: =C7=ROUND(SUM(E7:P7),2) -> TRUE | E7: =$C7*INDEX(Final!F:F,MATCH(Полуфабрикат!$B7,Final!$B:$B,0))/INDEX(Final!$T:$T,MATCH(Полуфабрикат!$B7,Final!$B:$B,0)) -> 0 | F7: =$C7*INDEX(Final!G:G,MATCH(Полуфабрикат!$B7,Final!$B:$B,0))/INDEX(Final!$T:$T,MATCH(Полуфабрикат!$B7,Final!$B:$B,0)) -> 0.004592145 | G7: =$C7*INDEX(Final!H:H,MATCH(Полуфабрикат!$B7,Final!$B:$B,0))/INDEX(Final!$T:$T,MATCH(Полуфабрикат!$B7,Final!$B:$B,0)) -> 0.12628399 | H7: =$C7*INDEX(Final!I:I,MATCH(Полуфабрикат!$B7,Final!$B:$B,0))/INDEX(Final!$T:$T,MATCH(Полуфабрикат!$B7,Final!$B:$B,0)) -> 0.35589124 | I7: =$C7*INDEX(Final!J:J,MATCH(Полуфабрикат!$B7,Final!$B:$B,0))/INDEX(Final!$T:$T,MATCH(Полуфабрикат!$B7,Final!$B:$B,0)) -> 0.56253776 | J7: =$C7*INDEX(Final!K:K,MATCH(Полуфабрикат!$B7,Final!$B:$B,0))/INDEX(Final!$T:$T,MATCH(Полуфабрикат!$B7,Final!$B:$B,0)) -> 0.3926284 | K7: =$C7*INDEX(Final!M:M,MATCH(Полуфабрикат!$B7,Final!$B:$B,0))/INDEX(Final!$T:$T,MATCH(Полуфабрикат!$B7,Final!$B:$B,0)) -> 0 | L7: =$C7*INDEX(Final!N:N,MATCH(Полуфабрикат!$B7,Final!$B:$B,0))/INDEX(Final!$T:$T,MATCH(Полуфабрикат!$B7,Final!$B:$B,0)) -> 0.004592145 | M7: =$C7*INDEX(Final!O:O,MATCH(Полуфабрикат!$B7,Final!$B:$B,0))/INDEX(Final!$T:$T,MATCH(Полуфабрикат!$B7,Final!$B:$B,0)) -> 0.10561934 | N7: =$C7*INDEX(Final!P:P,MATCH(Полуфабрикат!$B7,Final!$B:$B,0))/INDEX(Final!$T:$T,MATCH(Полуфабрикат!$B7,Final!$B:$B,0)) -> 0.24108761 | O7: =$C7*INDEX(Final!Q:Q,MATCH(Полуфабрикат!$B7,Final!$B:$B,0))/INDEX(Final!$T:$T,MATCH(Полуфабрикат!$B7,Final!$B:$B,0)) -> 0.2755287 | P7: =$C7*INDEX(Final!R:R,MATCH(Полуфабрикат!$B7,Final!$B:$B,0))/INDEX(Final!$T:$T,MATCH(Полуфабрикат!$B7,Final!$B:$B,0)) -> 0.21353474 | Q7: =SUM(R7:U7)=1 -> TRUE | R7: =INDEX(Final!$BJ:$BJ,MATCH(Полуфабрикат!$B7,Final!$B:$B,0))/INDEX(Final!$AX:$AX,MATCH(Полуфабрикат!$B7,Final!$B:$B,0)) -> 0.66430479 | S7: =INDEX(Final!$BE:$BE,MATCH(Полуфабрикат!$B7,Final!$B:$B,0))/INDEX(Final!$AX:$AX,MATCH(Полуфабрикат!$B7,Final!$B:$B,0)) -> 0.1830924 | T7: =INDEX(Final!$AY:$AY,MATCH(Полуфабрикат!$B7,Final!$B:$B,0))/INDEX(Final!$AX:$AX,MATCH(Полуфабрикат!$B7,Final!$B:$B,0)) -> 0.11193271 | U7: =INDEX(Final!$BL:$BL,MATCH(Полуфабрикат!$B7,Final!$B:$B,0))/INDEX(Final!$AX:$AX,MATCH(Полуфабрикат!$B7,Final!$B:$B,0)) -> 0.040670096 | V7: =SUM(W7:Z7)=1 -> TRUE | W7: =R7/SUM($R7:$U7) -> 0.66430479 | X7: =S7/SUM($R7:$U7) -> 0.1830924 | Y7: =T7/SUM($R7:$U7) -> 0.11193271 | Z7: =U7/SUM($R7:$U7) -> 0.040670096
A8: DIS05 | B8: Follow-up for lung cancer | C8: =INDEX(Final!$E:$E, MATCH(Полуфабрикат!$B8,Final!$B:$B,0)) -> 0.09 | D8: =C8=ROUND(SUM(E8:P8),2) -> TRUE | E8: =$C8*INDEX(Final!F:F,MATCH(Полуфабрикат!$B8,Final!$B:$B,0))/INDEX(Final!$T:$T,MATCH(Полуфабрикат!$B8,Final!$B:$B,0)) -> 0 | F8: =$C8*INDEX(Final!G:G,MATCH(Полуфабрикат!$B8,Final!$B:$B,0))/INDEX(Final!$T:$T,MATCH(Полуфабрикат!$B8,Final!$B:$B,0)) -> 0.00017208413 | G8: =$C8*INDEX(Final!H:H,MATCH(Полуфабрикат!$B8,Final!$B:$B,0))/INDEX(Final!$T:$T,MATCH(Полуфабрикат!$B8,Final!$B:$B,0)) -> 0.0032695985 | H8: =$C8*INDEX(Final!I:I,MATCH(Полуфабрикат!$B8,Final!$B:$B,0))/INDEX(Final!$T:$T,MATCH(Полуфабрикат!$B8,Final!$B:$B,0)) -> 0.011357553 | I8: =$C8*INDEX(Final!J:J,MATCH(Полуфабрикат!$B8,Final!$B:$B,0))/INDEX(Final!$T:$T,MATCH(Полуфабрикат!$B8,Final!$B:$B,0)) -> 0.0216826 | J8: =$C8*INDEX(Final!K:K,MATCH(Полуфабрикат!$B8,Final!$B:$B,0))/INDEX(Final!$T:$T,MATCH(Полуфабрикат!$B8,Final!$B:$B,0)) -> 0.019445507 | K8: =$C8*INDEX(Final!M:M,MATCH(Полуфабрикат!$B8,Final!$B:$B,0))/INDEX(Final!$T:$T,MATCH(Полуфабрикат!$B8,Final!$B:$B,0)) -> 0 | L8: =$C8*INDEX(Final!N:N,MATCH(Полуфабрикат!$B8,Final!$B:$B,0))/INDEX(Final!$T:$T,MATCH(Полуфабрикат!$B8,Final!$B:$B,0)) -> 0.00034416826 | M8: =$C8*INDEX(Final!O:O,MATCH(Полуфабрикат!$B8,Final!$B:$B,0))/INDEX(Final!$T:$T,MATCH(Полуфабрикат!$B8,Final!$B:$B,0)) -> 0.0032695985 | N8: =$C8*INDEX(Final!P:P,MATCH(Полуфабрикат!$B8,Final!$B:$B,0))/INDEX(Final!$T:$T,MATCH(Полуфабрикат!$B8,Final!$B:$B,0)) -> 0.0082600382 | O8: =$C8*INDEX(Final!Q:Q,MATCH(Полуфабрикат!$B8,Final!$B:$B,0))/INDEX(Final!$T:$T,MATCH(Полуфабрикат!$B8,Final!$B:$B,0)) -> 0.011185468 | P8: =$C8*INDEX(Final!R:R,MATCH(Полуфабрикат!$B8,Final!$B:$B,0))/INDEX(Final!$T:$T,MATCH(Полуфабрикат!$B8,Final!$B:$B,0)) -> 0.0108413 | Q8: =SUM(R8:U8)=1 -> FALSE | R8: =INDEX(Final!$BJ:$BJ,MATCH(Полуфабрикат!$B8,Final!$B:$B,0))/INDEX(Final!$AX:$AX,MATCH(Полуфабрикат!$B8,Final!$B:$B,0)) -> 0.31543259 | S8: =INDEX(Final!$BE:$BE,MATCH(Полуфабрикат!$B8,Final!$B:$B,0))/INDEX(Final!$AX:$AX,MATCH(Полуфабрикат!$B8,Final!$B:$B,0)) -> 0.23143052 | T8: =INDEX(Final!$AY:$AY,MATCH(Полуфабрикат!$B8,Final!$B:$B,0))/INDEX(Final!$AX:$AX,MATCH(Полуфабрикат!$B8,Final!$B:$B,0)) -> 0.28558164 | U8: =INDEX(Final!$BL:$BL,MATCH(Полуфабрикат!$B8,Final!$B:$B,0))/INDEX(Final!$AX:$AX,MATCH(Полуфабрикат!$B8,Final!$B:$B,0)) -> 0.16755397 | V8: =SUM(W8:Z8)=1 -> TRUE | W8: =R8/SUM($R8:$U8) -> 0.315433 | X8: =S8/SUM($R8:$U8) -> 0.23143082 | Y8: =T8/SUM($R8:$U8) -> 0.285582 | Z8: =U8/SUM($R8:$U8) -> 0.16755418
A9: DIS06 | B9: Active female breast cancer | C9: =INDEX(Final!$E:$E, MATCH(Полуфабрикат!$B9,Final!$B:$B,0)) -> 2.92 | D9: =C9=ROUND(SUM(E9:P9),2) -> TRUE | E9: =$C9*INDEX(Final!F:F,MATCH(Полуфабрикат!$B9,Final!$B:$B,0))/INDEX(Final!$T:$T,MATCH(Полуфабрикат!$B9,Final!$B:$B,0)) -> 0 | F9: =$C9*INDEX(Final!G:G,MATCH(Полуфабрикат!$B9,Final!$B:$B,0))/INDEX(Final!$T:$T,MATCH(Полуфабрикат!$B9,Final!$B:$B,0)) -> 0 | G9: =$C9*INDEX(Final!H:H,MATCH(Полуфабрикат!$B9,Final!$B:$B,0))/INDEX(Final!$T:$T,MATCH(Полуфабрикат!$B9,Final!$B:$B,0)) -> 0 | H9: =$C9*INDEX(Final!I:I,MATCH(Полуфабрикат!$B9,Final!$B:$B,0))/INDEX(Final!$T:$T,MATCH(Полуфабрикат!$B9,Final!$B:$B,0)) -> 0 | I9: =$C9*INDEX(Final!J:J,MATCH(Полуфабрикат!$B9,Final!$B:$B,0))/INDEX(Final!$T:$T,MATCH(Полуфабрикат!$B9,Final!$B:$B,0)) -> 0 | J9: =$C9*INDEX(Final!K:K,MATCH(Полуфабрикат!$B9,Final!$B:$B,0))/INDEX(Final!$T:$T,MATCH(Полуфабрикат!$B9,Final!$B:$B,0)) -> 0 | K9: =$C9*INDEX(Final!M:M,MATCH(Полуфабрикат!$B9,Final!$B:$B,0))/INDEX(Final!$T:$T,MATCH(Полуфабрикат!$B9,Final!$B:$B,0)) -> 0 | L9: =$C9*INDEX(Final!N:N,MATCH(Полуфабрикат!$B9,Final!$B:$B,0))/INDEX(Final!$T:$T,MATCH(Полуфабрикат!$B9,Final!$B:$B,0)) -> 0.039711007 | M9: =$C9*INDEX(Final!O:O,MATCH(Полуфабрикат!$B9,Final!$B:$B,0))/INDEX(Final!$T:$T,MATCH(Полуфабрикат!$B9,Final!$B:$B,0)) -> 0.76940076 | N9: =$C9*INDEX(Final!P:P,MATCH(Полуфабрикат!$B9,Final!$B:$B,0))/INDEX(Final!$T:$T,MATCH(Полуфабрикат!$B9,Final!$B:$B,0)) -> 0.63909902 | O9: =$C9*INDEX(Final!Q:Q,MATCH(Полуфабрикат!$B9,Final!$B:$B,0))/INDEX(Final!$T:$T,MATCH(Полуфабрикат!$B9,Final!$B:$B,0)) -> 0.78429239 | P9: =$C9*INDEX(Final!R:R,MATCH(Полуфабрикат!$B9,Final!$B:$B,0))/INDEX(Final!$T:$T,MATCH(Полуфабрикат!$B9,Final!$B:$B,0)) -> 0.68501487 | Q9: =SUM(R9:U9)=1 -> TRUE | R9: =INDEX(Final!$BJ:$BJ,MATCH(Полуфабрикат!$B9,Final!$B:$B,0))/INDEX(Final!$AX:$AX,MATCH(Полуфабрикат!$B9,Final!$B:$B,0)) -> 0.50196834 | S9: =INDEX(Final!$BE:$BE,MATCH(Полуфабрикат!$B9,Final!$B:$B,0))/INDEX(Final!$AX:$AX,MATCH(Полуфабрикат!$B9,Final!$B:$B,0)) -> 0.2056255 | T9: =INDEX(Final!$AY:$AY,MATCH(Полуфабрикат!$B9,Final!$B:$B,0))/INDEX(Final!$AX:$AX,MATCH(Полуфабрикат!$B9,Final!$B:$B,0)) -> 0.21594494 | U9: =INDEX(Final!$BL:$BL,MATCH(Полуфабрикат!$B9,Final!$B:$B,0))/INDEX(Final!$AX:$AX,MATCH(Полуфабрикат!$B9,Final!$B:$B,0)) -> 0.076461215 | V9: =SUM(W9:Z9)=1 -> TRUE | W9: =R9/SUM($R9:$U9) -> 0.50196834 | X9: =S9/SUM($R9:$U9) -> 0.2056255 | Y9: =T9/SUM($R9:$U9) -> 0.21594494 | Z9: =U9/SUM($R9:$U9) -> 0.076461215
A10: DIS07 | B10: Follow-up for female breast cancer | C10: =INDEX(Final!$E:$E, MATCH(Полуфабрикат!$B10,Final!$B:$B,0)) -> 0.58 | D10: =C10=ROUND(SUM(E10:P10),2) -> TRUE | E10: =$C10*INDEX(Final!F:F,MATCH(Полуфабрикат!$B10,Final!$B:$B,0))/INDEX(Final!$T:$T,MATCH(Полуфабрикат!$B10,Final!$B:$B,0)) -> 0 | F10: =$C10*INDEX(Final!G:G,MATCH(Полуфабрикат!$B10,Final!$B:$B,0))/INDEX(Final!$T:$T,MATCH(Полуфабрикат!$B10,Final!$B:$B,0)) -> 0 | G10: =$C10*INDEX(Final!H:H,MATCH(Полуфабрикат!$B10,Final!$B:$B,0))/INDEX(Final!$T:$T,MATCH(Полуфабрикат!$B10,Final!$B:$B,0)) -> 0 | H10: =$C10*INDEX(Final!I:I,MATCH(Полуфабрикат!$B10,Final!$B:$B,0))/INDEX(Final!$T:$T,MATCH(Полуфабрикат!$B10,Final!$B:$B,0)) -> 0 | I10: =$C10*INDEX(Final!J:J,MATCH(Полуфабрикат!$B10,Final!$B:$B,0))/INDEX(Final!$T:$T,MATCH(Полуфабрикат!$B10,Final!$B:$B,0)) -> 0 | J10: =$C10*INDEX(Final!K:K,MATCH(Полуфабрикат!$B10,Final!$B:$B,0))/INDEX(Final!$T:$T,MATCH(Полуфабрикат!$B10,Final!$B:$B,0)) -> 0 | K10: =$C10*INDEX(Final!M:M,MATCH(Полуфабрикат!$B10,Final!$B:$B,0))/INDEX(Final!$T:$T,MATCH(Полуфабрикат!$B10,Final!$B:$B,0)) -> 0 | L10: =$C10*INDEX(Final!N:N,MATCH(Полуфабрикат!$B10,Final!$B:$B,0))/INDEX(Final!$T:$T,MATCH(Полуфабрикат!$B10,Final!$B:$B,0)) -> 0.0015322089 | M10: =$C10*INDEX(Final!O:O,MATCH(Полуфабрикат!$B10,Final!$B:$B,0))/INDEX(Final!$T:$T,MATCH(Полуфабрикат!$B10,Final!$B:$B,0)) -> 0.081560658 | N10: =$C10*INDEX(Final!P:P,MATCH(Полуфабрикат!$B10,Final!$B:$B,0))/INDEX(Final!$T:$T,MATCH(Полуфабрикат!$B10,Final!$B:$B,0)) -> 0.1238732 | O10: =$C10*INDEX(Final!Q:Q,MATCH(Полуфабрикат!$B10,Final!$B:$B,0))/INDEX(Final!$T:$T,MATCH(Полуфабрикат!$B10,Final!$B:$B,0)) -> 0.17054664 | P10: =$C10*INDEX(Final!R:R,MATCH(Полуфабрикат!$B10,Final!$B:$B,0))/INDEX(Final!$T:$T,MATCH(Полуфабрикат!$B10,Final!$B:$B,0)) -> 0.20236944 | Q10: =SUM(R10:U10)=1 -> FALSE | R10: =INDEX(Final!$BJ:$BJ,MATCH(Полуфабрикат!$B10,Final!$B:$B,0))/INDEX(Final!$AX:$AX,MATCH(Полуфабрикат!$B10,Final!$B:$B,0)) -> 0.27906387 | S10: =INDEX(Final!$BE:$BE,MATCH(Полуфабрикат!$B10,Final!$B:$B,0))/INDEX(Final!$AX:$AX,MATCH(Полуфабрикат!$B10,Final!$B:$B,0)) -> 0.02464613 | T10: =INDEX(Final!$AY:$AY,MATCH(Полуфабрикат!$B10,Final!$B:$B,0))/INDEX(Final!$AX:$AX,MATCH(Полуфабрикат!$B10,Final!$B:$B,0)) -> 0.6798734 | U10: =INDEX(Final!$BL:$BL,MATCH(Полуфабрикат!$B10,Final!$B:$B,0))/INDEX(Final!$AX:$AX,MATCH(Полуфабрикат!$B10,Final!$B:$B,0)) -> 0.016417011 | V10: =SUM(W10:Z10)=1 -> TRUE | W10: =R10/SUM($R10:$U10) -> 0.27906376 | X10: =S10/SUM($R10:$U10) -> 0.024646119 | Y10: =T10/SUM($R10:$U10) -> 0.67987312 | Z10: =U10/SUM($R10:$U10) -> 0.016417004
A11: DIS08 | B11: Active prostate cancer | C11: =INDEX(Final!$E:$E, MATCH(Полуфабрикат!$B11,Final!$B:$B,0)) -> 1.54 | D11: =C11=ROUND(SUM(E11:P11),2) -> TRUE | E11: =$C11*INDEX(Final!F:F,MATCH(Полуфабрикат!$B11,Final!$B:$B,0))/INDEX(Final!$T:$T,MATCH(Полуфабрикат!$B11,Final!$B:$B,0)) -> 0 | F11: =$C11*INDEX(Final!G:G,MATCH(Полуфабрикат!$B11,Final!$B:$B,0))/INDEX(Final!$T:$T,MATCH(Полуфабрикат!$B11,Final!$B:$B,0)) -> 0 | G11: =$C11*INDEX(Final!H:H,MATCH(Полуфабрикат!$B11,Final!$B:$B,0))/INDEX(Final!$T:$T,MATCH(Полуфабрикат!$B11,Final!$B:$B,0)) -> 0.033038529 | H11: =$C11*INDEX(Final!I:I,MATCH(Полуфабрикат!$B11,Final!$B:$B,0))/INDEX(Final!$T:$T,MATCH(Полуфабрикат!$B11,Final!$B:$B,0)) -> 0.21845884 | I11: =$C11*INDEX(Final!J:J,MATCH(Полуфабрикат!$B11,Final!$B:$B,0))/INDEX(Final!$T:$T,MATCH(Полуфабрикат!$B11,Final!$B:$B,0)) -> 0.57985989 | J11: =$C11*INDEX(Final!K:K,MATCH(Полуфабрикат!$B11,Final!$B:$B,0))/INDEX(Final!$T:$T,MATCH(Полуфабрикат!$B11,Final!$B:$B,0)) -> 0.70796848 | K11: =$C11*INDEX(Final!M:M,MATCH(Полуфабрикат!$B11,Final!$B:$B,0))/INDEX(Final!$T:$T,MATCH(Полуфабрикат!$B11,Final!$B:$B,0)) -> 0 | L11: =$C11*INDEX(Final!N:N,MATCH(Полуфабрикат!$B11,Final!$B:$B,0))/INDEX(Final!$T:$T,MATCH(Полуфабрикат!$B11,Final!$B:$B,0)) -> 0 | M11: =$C11*INDEX(Final!O:O,MATCH(Полуфабрикат!$B11,Final!$B:$B,0))/INDEX(Final!$T:$T,MATCH(Полуфабрикат!$B11,Final!$B:$B,0)) -> 0 | N11: =$C11*INDEX(Final!P:P,MATCH(Полуфабрикат!$B11,Final!$B:$B,0))/INDEX(Final!$T:$T,MATCH(Полуфабрикат!$B11,Final!$B:$B,0)) -> 0 | O11: =$C11*INDEX(Final!Q:Q,MATCH(Полуфабрикат!$B11,Final!$B:$B,0))/INDEX(Final!$T:$T,MATCH(Полуфабрикат!$B11,Final!$B:$B,0)) -> 0 | P11: =$C11*INDEX(Final!R:R,MATCH(Полуфабрикат!$B11,Final!$B:$B,0))/INDEX(Final!$T:$T,MATCH(Полуфабрикат!$B11,Final!$B:$B,0)) -> 0 | Q11: =SUM(R11:U11)=1 -> FALSE | R11: =INDEX(Final!$BJ:$BJ,MATCH(Полуфабрикат!$B11,Final!$B:$B,0))/INDEX(Final!$AX:$AX,MATCH(Полуфабрикат!$B11,Final!$B:$B,0)) -> 0.3328474 | S11: =INDEX(Final!$BE:$BE,MATCH(Полуфабрикат!$B11,Final!$B:$B,0))/INDEX(Final!$AX:$AX,MATCH(Полуфабрикат!$B11,Final!$B:$B,0)) -> 0.36292148 | T11: =INDEX(Final!$AY:$AY,MATCH(Полуфабрикат!$B11,Final!$B:$B,0))/INDEX(Final!$AX:$AX,MATCH(Полуфабрикат!$B11,Final!$B:$B,0)) -> 0.28134767 | U11: =INDEX(Final!$BL:$BL,MATCH(Полуфабрикат!$B11,Final!$B:$B,0))/INDEX(Final!$AX:$AX,MATCH(Полуфабрикат!$B11,Final!$B:$B,0)) -> 0.022884048 | V11: =SUM(W11:Z11)=1 -> TRUE | W11: =R11/SUM($R11:$U11) -> 0.3328472 | X11: =S11/SUM($R11:$U11) -> 0.36292126 | Y11: =T11/SUM($R11:$U11) -> 0.2813475 | Z11: =U11/SUM($R11:$U11) -> 0.022884034
A12: DIS09 | B12: Follow-up for prostate cancer | C12: =INDEX(Final!$E:$E, MATCH(Полуфабрикат!$B12,Final!$B:$B,0)) -> 0.95 | D12: =C12=ROUND(SUM(E12:P12),2) -> TRUE | E12: =$C12*INDEX(Final!F:F,MATCH(Полуфабрикат!$B12,Final!$B:$B,0))/INDEX(Final!$T:$T,MATCH(Полуфабрикат!$B12,Final!$B:$B,0)) -> 0 | F12: =$C12*INDEX(Final!G:G,MATCH(Полуфабрикат!$B12,Final!$B:$B,0))/INDEX(Final!$T:$T,MATCH(Полуфабрикат!$B12,Final!$B:$B,0)) -> 0.00030546624 | G12: =$C12*INDEX(Final!H:H,MATCH(Полуфабрикат!$B12,Final!$B:$B,0))/INDEX(Final!$T:$T,MATCH(Полуфабрикат!$B12,Final!$B:$B,0)) -> 0.0061093248 | H12: =$C12*INDEX(Final!I:I,MATCH(Полуфабрикат!$B12,Final!$B:$B,0))/INDEX(Final!$T:$T,MATCH(Полуфабрикат!$B12,Final!$B:$B,0)) -> 0.090418006 | I12: =$C12*INDEX(Final!J:J,MATCH(Полуфабрикат!$B12,Final!$B:$B,0))/INDEX(Final!$T:$T,MATCH(Полуфабрикат!$B12,Final!$B:$B,0)) -> 0.34334405 | J12: =$C12*INDEX(Final!K:K,MATCH(Полуфабрикат!$B12,Final!$B:$B,0))/INDEX(Final!$T:$T,MATCH(Полуфабрикат!$B12,Final!$B:$B,0)) -> 0.51012862 | K12: =$C12*INDEX(Final!M:M,MATCH(Полуфабрикат!$B12,Final!$B:$B,0))/INDEX(Final!$T:$T,MATCH(Полуфабрикат!$B12,Final!$B:$B,0)) -> 0 | L12: =$C12*INDEX(Final!N:N,MATCH(Полуфабрикат!$B12,Final!$B:$B,0))/INDEX(Final!$T:$T,MATCH(Полуфабрикат!$B12,Final!$B:$B,0)) -> 0 | M12: =$C12*INDEX(Final!O:O,MATCH(Полуфабрикат!$B12,Final!$B:$B,0))/INDEX(Final!$T:$T,MATCH(Полуфабрикат!$B12,Final!$B:$B,0)) -> 0 | N12: =$C12*INDEX(Final!P:P,MATCH(Полуфабрикат!$B12,Final!$B:$B,0))/INDEX(Final!$T:$T,MATCH(Полуфабрикат!$B12,Final!$B:$B,0)) -> 0 | O12: =$C12*INDEX(Final!Q:Q,MATCH(Полуфабрикат!$B12,Final!$B:$B,0))/INDEX(Final!$T:$T,MATCH(Полуфабрикат!$B12,Final!$B:$B,0)) -> 0 | P12: =$C12*INDEX(Final!R:R,MATCH(Полуфабрикат!$B12,Final!$B:$B,0))/INDEX(Final!$T:$T,MATCH(Полуфабрикат!$B12,Final!$B:$B,0)) -> 0 | Q12: =SUM(R12:U12)=1 -> TRUE | R12: =INDEX(Final!$BJ:$BJ,MATCH(Полуфабрикат!$B12,Final!$B:$B,0))/INDEX(Final!$AX:$AX,MATCH(Полуфабрикат!$B12,Final!$B:$B,0)) -> 0.12189225 | S12: =INDEX(Final!$BE:$BE,MATCH(Полуфабрикат!$B12,Final!$B:$B,0))/INDEX(Final!$AX:$AX,MATCH(Полуфабрикат!$B12,Final!$B:$B,0)) -> 0.8080034 | T12: =INDEX(Final!$AY:$AY,MATCH(Полуфабрикат!$B12,Final!$B:$B,0))/INDEX(Final!$AX:$AX,MATCH(Полуфабрикат!$B12,Final!$B:$B,0)) -> 0.046952521 | U12: =INDEX(Final!$BL:$BL,MATCH(Полуфабрикат!$B12,Final!$B:$B,0))/INDEX(Final!$AX:$AX,MATCH(Полуфабрикат!$B12,Final!$B:$B,0)) -> 0.023151831 | V12: =SUM(W12:Z12)=1 -> TRUE | W12: =R12/SUM($R12:$U12) -> 0.12189225 | X12: =S12/SUM($R12:$U12) -> 0.8080034 | Y12: =T12/SUM($R12:$U12) -> 0.046952521 | Z12: =U12/SUM($R12:$U12) -> 0.023151831
A13: DIS10 | B13: Other active cancers | C13: =INDEX(Final!$E:$E, MATCH(Полуфабрикат!$B13,Final!$B:$B,0)) -> 9.59 | D13: =C13=ROUND(SUM(E13:P13),2) -> TRUE | E13: =$C13*INDEX(Final!F:F,MATCH(Полуфабрикат!$B13,Final!$B:$B,0))/INDEX(Final!$T:$T,MATCH(Полуфабрикат!$B13,Final!$B:$B,0)) -> 0.049643727 | F13: =$C13*INDEX(Final!G:G,MATCH(Полуфабрикат!$B13,Final!$B:$B,0))/INDEX(Final!$T:$T,MATCH(Полуфабрикат!$B13,Final!$B:$B,0)) -> 0.14844448 | G13: =$C13*INDEX(Final!H:H,MATCH(Полуфабрикат!$B13,Final!$B:$B,0))/INDEX(Final!$T:$T,MATCH(Полуфабрикат!$B13,Final!$B:$B,0)) -> 0.56700924 | H13: =$C13*INDEX(Final!I:I,MATCH(Полуфабрикат!$B13,Final!$B:$B,0))/INDEX(Final!$T:$T,MATCH(Полуфабрикат!$B13,Final!$B:$B,0)) -> 0.83737287 | I13: =$C13*INDEX(Final!J:J,MATCH(Полуфабрикат!$B13,Final!$B:$B,0))/INDEX(Final!$T:$T,MATCH(Полуфабрикат!$B13,Final!$B:$B,0)) -> 1.4146029 | J13: =$C13*INDEX(Final!K:K,MATCH(Полуфабрикат!$B13,Final!$B:$B,0))/INDEX(Final!$T:$T,MATCH(Полуфабрикат!$B13,Final!$B:$B,0)) -> 1.9098234 | K13: =$C13*INDEX(Final!M:M,MATCH(Полуфабрикат!$B13,Final!$B:$B,0))/INDEX(Final!$T:$T,MATCH(Полуфабрикат!$B13,Final!$B:$B,0)) -> 0.03942296 | L13: =$C13*INDEX(Final!N:N,MATCH(Полуфабрикат!$B13,Final!$B:$B,0))/INDEX(Final!$T:$T,MATCH(Полуфабрикат!$B13,Final!$B:$B,0)) -> 0.21244595 | M13: =$C13*INDEX(Final!O:O,MATCH(Полуфабрикат!$B13,Final!$B:$B,0))/INDEX(Final!$T:$T,MATCH(Полуфабрикат!$B13,Final!$B:$B,0)) -> 0.75560673 | N13: =$C13*INDEX(Final!P:P,MATCH(Полуфабрикат!$B13,Final!$B:$B,0))/INDEX(Final!$T:$T,MATCH(Полуфабрикат!$B13,Final!$B:$B,0)) -> 0.74757613 | O13: =$C13*INDEX(Final!Q:Q,MATCH(Полуфабрикат!$B13,Final!$B:$B,0))/INDEX(Final!$T:$T,MATCH(Полуфабрикат!$B13,Final!$B:$B,0)) -> 1.1157671 | P13: =$C13*INDEX(Final!R:R,MATCH(Полуфабрикат!$B13,Final!$B:$B,0))/INDEX(Final!$T:$T,MATCH(Полуфабрикат!$B13,Final!$B:$B,0)) -> 1.7883909 | Q13: =SUM(R13:U13)=1 -> TRUE | R13: =INDEX(Final!$BJ:$BJ,MATCH(Полуфабрикат!$B13,Final!$B:$B,0))/INDEX(Final!$AX:$AX,MATCH(Полуфабрикат!$B13,Final!$B:$B,0)) -> 0.62013889 | S13: =INDEX(Final!$BE:$BE,MATCH(Полуфабрикат!$B13,Final!$B:$B,0))/INDEX(Final!$AX:$AX,MATCH(Полуфабрикат!$B13,Final!$B:$B,0)) -> 0.22908801 | T13: =INDEX(Final!$AY:$AY,MATCH(Полуфабрикат!$B13,Final!$B:$B,0))/INDEX(Final!$AX:$AX,MATCH(Полуфабрикат!$B13,Final!$B:$B,0)) -> 0.11494551 | U13: =INDEX(Final!$BL:$BL,MATCH(Полуфабрикат!$B13,Final!$B:$B,0))/INDEX(Final!$AX:$AX,MATCH(Полуфабрикат!$B13,Final!$B:$B,0)) -> 0.035827596 | V13: =SUM(W13:Z13)=1 -> TRUE | W13: =R13/SUM($R13:$U13) -> 0.62013889 | X13: =S13/SUM($R13:$U13) -> 0.22908801 | Y13: =T13/SUM($R13:$U13) -> 0.11494551 | Z13: =U13/SUM($R13:$U13) -> 0.035827596
A14: DIS11 | B14: Follow-up for other cancers | C14: =INDEX(Final!$E:$E, MATCH(Полуфабрикат!$B14,Final!$B:$B,0)) -> 0.95 | D14: =C14=ROUND(SUM(E14:P14),2) -> TRUE | E14: =$C14*INDEX(Final!F:F,MATCH(Полуфабрикат!$B14,Final!$B:$B,0))/INDEX(Final!$T:$T,MATCH(Полуфабрикат!$B14,Final!$B:$B,0)) -> 0.0040382572 | F14: =$C14*INDEX(Final!G:G,MATCH(Полуфабрикат!$B14,Final!$B:$B,0))/INDEX(Final!$T:$T,MATCH(Полуфабрикат!$B14,Final!$B:$B,0)) -> 0.014748418 | G14: =$C14*INDEX(Final!H:H,MATCH(Полуфабрикат!$B14,Final!$B:$B,0))/INDEX(Final!$T:$T,MATCH(Полуфабрикат!$B14,Final!$B:$B,0)) -> 0.055262672 | H14: =$C14*INDEX(Final!I:I,MATCH(Полуфабрикат!$B14,Final!$B:$B,0))/INDEX(Final!$T:$T,MATCH(Полуфабрикат!$B14,Final!$B:$B,0)) -> 0.073039782 | I14: =$C14*INDEX(Final!J:J,MATCH(Полуфабрикат!$B14,Final!$B:$B,0))/INDEX(Final!$T:$T,MATCH(Полуфабрикат!$B14,Final!$B:$B,0)) -> 0.12672227 | J14: =$C14*INDEX(Final!K:K,MATCH(Полуфабрикат!$B14,Final!$B:$B,0))/INDEX(Final!$T:$T,MATCH(Полуфабрикат!$B14,Final!$B:$B,0)) -> 0.18558425 | K14: =$C14*INDEX(Final!M:M,MATCH(Полуфабрикат!$B14,Final!$B:$B,0))/INDEX(Final!$T:$T,MATCH(Полуфабрикат!$B14,Final!$B:$B,0)) -> 0.0032920575 | L14: =$C14*INDEX(Final!N:N,MATCH(Полуфабрикат!$B14,Final!$B:$B,0))/INDEX(Final!$T:$T,MATCH(Полуфабрикат!$B14,Final!$B:$B,0)) -> 0.021552003 | M14: =$C14*INDEX(Final!O:O,MATCH(Полуфабрикат!$B14,Final!$B:$B,0))/INDEX(Final!$T:$T,MATCH(Полуфабрикат!$B14,Final!$B:$B,0)) -> 0.084101095 | N14: =$C14*INDEX(Final!P:P,MATCH(Полуфабрикат!$B14,Final!$B:$B,0))/INDEX(Final!$T:$T,MATCH(Полуфабрикат!$B14,Final!$B:$B,0)) -> 0.076990251 | O14: =$C14*INDEX(Final!Q:Q,MATCH(Полуфабрикат!$B14,Final!$B:$B,0))/INDEX(Final!$T:$T,MATCH(Полуфабрикат!$B14,Final!$B:$B,0)) -> 0.11043755 | P14: =$C14*INDEX(Final!R:R,MATCH(Полуфабрикат!$B14,Final!$B:$B,0))/INDEX(Final!$T:$T,MATCH(Полуфабрикат!$B14,Final!$B:$B,0)) -> 0.19423139 | Q14: =SUM(R14:U14)=1 -> TRUE | R14: =INDEX(Final!$BJ:$BJ,MATCH(Полуфабрикат!$B14,Final!$B:$B,0))/INDEX(Final!$AX:$AX,MATCH(Полуфабрикат!$B14,Final!$B:$B,0)) -> 0.11159517 | S14: =INDEX(Final!$BE:$BE,MATCH(Полуфабрикат!$B14,Final!$B:$B,0))/INDEX(Final!$AX:$AX,MATCH(Полуфабрикат!$B14,Final!$B:$B,0)) -> 0.19521511 | T14: =INDEX(Final!$AY:$AY,MATCH(Полуфабрикат!$B14,Final!$B:$B,0))/INDEX(Final!$AX:$AX,MATCH(Полуфабрикат!$B14,Final!$B:$B,0)) -> 0.43675594 | U14: =INDEX(Final!$BL:$BL,MATCH(Полуфабрикат!$B14,Final!$B:$B,0))/INDEX(Final!$AX:$AX,MATCH(Полуфабрикат!$B14,Final!$B:$B,0)) -> 0.25643377 | V14: =SUM(W14:Z14)=1 -> TRUE | W14: =R14/SUM($R14:$U14) -> 0.11159517 | X14: =S14/SUM($R14:$U14) -> 0.19521511 | Y14: =T14/SUM($R14:$U14) -> 0.43675594 | Z14: =U14/SUM($R14:$U14) -> 0.25643377
A15: DIS12 | B15: Hemophilia or severe hemostasis disorders | C15: =INDEX(Final!$E:$E, MATCH(Полуфабрикат!$B15,Final!$B:$B,0)) -> 0.57 | D15: =C15=ROUND(SUM(E15:P15),2) -> TRUE | E15: =$C15*INDEX(Final!F:F,MATCH(Полуфабрикат!$B15,Final!$B:$B,0))/INDEX(Final!$T:$T,MATCH(Полуфабрикат!$B15,Final!$B:$B,0)) -> 0.027242647 | F15: =$C15*INDEX(Final!G:G,MATCH(Полуфабрикат!$B15,Final!$B:$B,0))/INDEX(Final!$T:$T,MATCH(Полуфабрикат!$B15,Final!$B:$B,0)) -> 0.045055147 | G15: =$C15*INDEX(Final!H:H,MATCH(Полуфабрикат!$B15,Final!$B:$B,0))/INDEX(Final!$T:$T,MATCH(Полуфабрикат!$B15,Final!$B:$B,0)) -> 0.067058824 | H15: =$C15*INDEX(Final!I:I,MATCH(Полуфабрикат!$B15,Final!$B:$B,0))/INDEX(Final!$T:$T,MATCH(Полуфабрикат!$B15,Final!$B:$B,0)) -> 0.044007353 | I15: =$C15*INDEX(Final!J:J,MATCH(Полуфабрикат!$B15,Final!$B:$B,0))/INDEX(Final!$T:$T,MATCH(Полуфабрикат!$B15,Final!$B:$B,0)) -> 0.049246324 | J15: =$C15*INDEX(Final!K:K,MATCH(Полуфабрикат!$B15,Final!$B:$B,0))/INDEX(Final!$T:$T,MATCH(Полуфабрикат!$B15,Final!$B:$B,0)) -> 0.042959559 | K15: =$C15*INDEX(Final!M:M,MATCH(Полуфабрикат!$B15,Final!$B:$B,0))/INDEX(Final!$T:$T,MATCH(Полуфабрикат!$B15,Final!$B:$B,0)) -> 0.010477941 | L15: =$C15*INDEX(Final!N:N,MATCH(Полуфабрикат!$B15,Final!$B:$B,0))/INDEX(Final!$T:$T,MATCH(Полуфабрикат!$B15,Final!$B:$B,0)) -> 0.041911765 | M15: =$C15*INDEX(Final!O:O,MATCH(Полуфабрикат!$B15,Final!$B:$B,0))/INDEX(Final!$T:$T,MATCH(Полуфабрикат!$B15,Final!$B:$B,0)) -> 0.086966912 | N15: =$C15*INDEX(Final!P:P,MATCH(Полуфабрикат!$B15,Final!$B:$B,0))/INDEX(Final!$T:$T,MATCH(Полуфабрикат!$B15,Final!$B:$B,0)) -> 0.049246324 | O15: =$C15*INDEX(Final!Q:Q,MATCH(Полуфабрикат!$B15,Final!$B:$B,0))/INDEX(Final!$T:$T,MATCH(Полуфабрикат!$B15,Final!$B:$B,0)) -> 0.048198529 | P15: =$C15*INDEX(Final!R:R,MATCH(Полуфабрикат!$B15,Final!$B:$B,0))/INDEX(Final!$T:$T,MATCH(Полуфабрикат!$B15,Final!$B:$B,0)) -> 0.057628676 | Q15: =SUM(R15:U15)=1 -> TRUE | R15: =INDEX(Final!$BJ:$BJ,MATCH(Полуфабрикат!$B15,Final!$B:$B,0))/INDEX(Final!$AX:$AX,MATCH(Полуфабрикат!$B15,Final!$B:$B,0)) -> 0.75266769 | S15: =INDEX(Final!$BE:$BE,MATCH(Полуфабрикат!$B15,Final!$B:$B,0))/INDEX(Final!$AX:$AX,MATCH(Полуфабрикат!$B15,Final!$B:$B,0)) -> 0.028103891 | T15: =INDEX(Final!$AY:$AY,MATCH(Полуфабрикат!$B15,Final!$B:$B,0))/INDEX(Final!$AX:$AX,MATCH(Полуфабрикат!$B15,Final!$B:$B,0)) -> 0.11830619 | U15: =INDEX(Final!$BL:$BL,MATCH(Полуфабрикат!$B15,Final!$B:$B,0))/INDEX(Final!$AX:$AX,MATCH(Полуфабрикат!$B15,Final!$B:$B,0)) -> 0.10092224 | V15: =SUM(W15:Z15)=1 -> TRUE | W15: =R15/SUM($R15:$U15) -> 0.75266769 | X15: =S15/SUM($R15:$U15) -> 0.028103891 | Y15: =T15/SUM($R15:$U15) -> 0.11830619 | Z15: =U15/SUM($R15:$U15) -> 0.10092224
... A59: DIS56 | B59: Other long-term diseases | C59: =INDEX(Final!$E:$E, MATCH(Полуфабрикат!$B59,Final!$B:$B,0)) -> 4.3 | D59: =C59=ROUND(SUM(E59:P59),2) -> TRUE | E59: =$C59*INDEX(Final!F:F,MATCH(Полуфабрикат!$B59,Final!$B:$B,0))/INDEX(Final!$T:$T,MATCH(Полуфабрикат!$B59,Final!$B:$B,0)) -> 0.097909624 | F59: =$C59*INDEX(Final!G:G,MATCH(Полуфабрикат!$B59,Final!$B:$B,0))/INDEX(Final!$T:$T,MATCH(Полуфабрикат!$B59,Final!$B:$B,0)) -> 0.147097 | G59: =$C59*INDEX(Final!H:H,MATCH(Полуфабрикат!$B59,Final!$B:$B,0))/INDEX(Final!$T:$T,MATCH(Полуфабрикат!$B59,Final!$B:$B,0)) -> 0.34349766 | H59: =$C59*INDEX(Final!I:I,MATCH(Полуфабрикат!$B59,Final!$B:$B,0))/INDEX(Final!$T:$T,MATCH(Полуфабрикат!$B59,Final!$B:$B,0)) -> 0.35942832 | I59: =$C59*INDEX(Final!J:J,MATCH(Полуфабрикат!$B59,Final!$B:$B,0))/INDEX(Final!$T:$T,MATCH(Полуфабрикат!$B59,Final!$B:$B,0)) -> 0.51629303 | J59: =$C59*INDEX(Final!K:K,MATCH(Полуфабрикат!$B59,Final!$B:$B,0))/INDEX(Final!$T:$T,MATCH(Полуфабрикат!$B59,Final!$B:$B,0)) -> 0.58245761 | K59: =$C59*INDEX(Final!M:M,MATCH(Полуфабрикат!$B59,Final!$B:$B,0))/INDEX(Final!$T:$T,MATCH(Полуфабрикат!$B59,Final!$B:$B,0)) -> 0.078606777 | L59: =$C59*INDEX(Final!N:N,MATCH(Полуфабрикат!$B59,Final!$B:$B,0))/INDEX(Final!$T:$T,MATCH(Полуфабрикат!$B59,Final!$B:$B,0)) -> 0.17663268 | M59: =$C59*INDEX(Final!O:O,MATCH(Полуфабрикат!$B59,Final!$B:$B,0))/INDEX(Final!$T:$T,MATCH(Полуфабрикат!$B59,Final!$B:$B,0)) -> 0.34024176 | N59: =$C59*INDEX(Final!P:P,MATCH(Полуфабрикат!$B59,Final!$B:$B,0))/INDEX(Final!$T:$T,MATCH(Полуфабрикат!$B59,Final!$B:$B,0)) -> 0.32338084 | O59: =$C59*INDEX(Final!Q:Q,MATCH(Полуфабрикат!$B59,Final!$B:$B,0))/INDEX(Final!$T:$T,MATCH(Полуфабрикат!$B59,Final!$B:$B,0)) -> 0.51047892 | P59: =$C59*INDEX(Final!R:R,MATCH(Полуфабрикат!$B59,Final!$B:$B,0))/INDEX(Final!$T:$T,MATCH(Полуфабрикат!$B59,Final!$B:$B,0)) -> 0.82455718 | Q59: =SUM(R59:U59)=1 -> TRUE | R59: =INDEX(Final!$BJ:$BJ,MATCH(Полуфабрикат!$B59,Final!$B:$B,0))/INDEX(Final!$AX:$AX,MATCH(Полуфабрикат!$B59,Final!$B:$B,0)) -> 0.37535044 | S59: =INDEX(Final!$BE:$BE,MATCH(Полуфабрикат!$B59,Final!$B:$B,0))/INDEX(Final!$AX:$AX,MATCH(Полуфабрикат!$B59,Final!$B:$B,0)) -> 0.20679324 | T59: =INDEX(Final!$AY:$AY,MATCH(Полуфабрикат!$B59,Final!$B:$B,0))/INDEX(Final!$AX:$AX,MATCH(Полуфабрикат!$B59,Final!$B:$B,0)) -> 0.26119527 | U59: =INDEX(Final!$BL:$BL,MATCH(Полуфабрикат!$B59,Final!$B:$B,0))/INDEX(Final!$AX:$AX,MATCH(Полуфабрикат!$B59,Final!$B:$B,0)) -> 0.15666105 | V59: =SUM(W59:Z59)=1 -> TRUE | W59: =R59/SUM($R59:$U59) -> 0.37535044 | X59: =S59/SUM($R59:$U59) -> 0.20679324 | Y59: =T59/SUM($R59:$U59) -> 0.26119527 | Z59: =U59/SUM($R59:$U59) -> 0.15666105

Sheet Final
C1: The Economic Burden of Disease in France From the National Health Insurance Perspective 10.1097/MLR.0000000000001745 | F1: Number of patients by pathology and age group according to gender. French National Insurer. https://www.assurance-maladie.ameli.fr/etudes-et-donnees/cartographie-effectif-patients-par-pathologie-age-sexe | AW1: Reimbursed expenses allocated to each pathology. French National Insurer. https://www.data.gouv.fr/datasets/pathologies-depenses-remboursees-affectees-a-chaque-pathologie/
A2: Group in PAID | B2: matched_reference | C2: n | D2: Prevalence (%) | E2: Expenditures (In Billion €) | F2: EFF_eff_M_00_14 | G2: EFF_eff_M_15_34 | H2: EFF_eff_M_35_54 | I2: EFF_eff_M_55_64 | J2: EFF_eff_M_65_74 | K2: EFF_eff_M_75_pl | L2: EFF_eff_M_total | M2: EFF_eff_F_00_14 | N2: EFF_eff_F_15_34 | O2: EFF_eff_F_35_54 | P2: EFF_eff_F_55_64 | Q2: EFF_eff_F_65_74 | R2: EFF_eff_F_75_pl | S2: EFF_eff_F_total | T2: Total | U2: EFF_share_M_00_14 | V2: EFF_share_M_15_34 | W2: EFF_share_M_35_54 | X2: EFF_share_M_55_64 | Y2: EFF_share_M_65_74 | Z2: EFF_share_M_75_pl | AA2: EFF_share_M_total | AB2: EFF_share_F_00_14 | AC2: EFF_share_F_15_34 | AD2: EFF_share_F_35_54 | AE2: EFF_share_F_55_64 | AF2: EFF_share_F_65_74 | AG2: EFF_share_F_75_pl | AH2: EFF_share_F_total | AI2: EXP_share_M_00_14 | AJ2: EXP_share_M_15_34 | AK2: EXP_share_M_35_54 | AL2: EXP_share_M_55_64 | AM2: EXP_share_M_65_74 | AN2: EXP_share_M_75_pl | AO2: EXP_share_M_total | AP2: EXP_share_F_00_14 | AQ2: EXP_share_F_15_34 | AR2: EXP_share_F_35_54 | AS2: EXP_share_F_55_64 | AT2: EXP_share_F_65_74 | AU2: EXP_share_F_75_pl | AV2: EXP_share_F_total | AW2: DEP_Effectif | AX2: DEP_total | AY2: GP | AZ2: DEP_total_outpatient | BA2: DEP_physician | BB2: DEP_nurse | BC2: DEP_physiotherapist | BD2: DEP_other_providers | BE2: DEP_medicines | BF2: DEP_other_health_products | BG2: DEP_lab | BH2: DEP_transports | BI2: DEP_outpatient_other | BJ2: DEP_total_hospit | BK2: DEP_including_medicine_surgery_obstetrics | BL2: DEP_benefit | BM2: DEP_including_sick_leave_benefit | BN2: DEP_share_total_outpatient | BO2: DEP_share_physician | BP2: DEP_share_nurse | BQ2: DEP_share_physiotherapist | BR2: DEP_share_other_providers | BS2: DEP_share_medicines | BT2: DEP_share_other_health_products | BU2: DEP_share_lab | BV2: DEP_share_transports | BW2: DEP_share_outpatient_other | BX2: DEP_share_total_hospit | BY2: DEP_share_including_medicine_surgery_obstetrics | BZ2: DEP_share_benefit | CA2: DEP_share_including_sick_leave_benefit | CB2: EXP_share_total_outpatient | CC2: EXP_share_physician | CD2: EXP_share_nurse | CE2: EXP_share_physiotherapist | CF2: EXP_share_other_providers | CG2: EXP_share_medicines | CH2: EXP_share_other_health_products | CI2: EXP_share_lab | CJ2: EXP_share_transports | CK2: EXP_share_outpatient_other | CL2: EXP_share_total_hospit | CM2: EXP_share_including_medicine_surgery_obstetrics | CN2: EXP_share_benefit | CO2: EXP_share_including_sick_leave_benefit
A3: 2 | B3: Active colorectal cancer | C3: 150434 | D3: 0.23 | E3: 1.67 | F3: 0 | G3: 700 | H3: 7700 | I3: 16500 | J3: 30400 | K3: 32300 | L3: 87500 | M3: 0 | N3: 700 | O3: 7600 | P3: 12500 | Q3: 19900 | R3: 28100 | S3: 68800 | T3: =L3+S3 -> 156300 | U3: =F3/$T3 -> 0 | V3: =G3/$T3 -> 0.0044785669 | W3: =H3/$T3 -> 0.049264235 | X3: =I3/$T3 -> 0.10556622 | Y3: =J3/$T3 -> 0.19449776 | Z3: =K3/$T3 -> 0.20665387 | AA3: =L3/$T3 -> 0.55982086 | AB3: =M3/$T3 -> 0 | ... AH3: =S3/$T3 -> 0.44017914 | AI3: =U3*$E3 -> 0 | AJ3: =V3*$E3 -> 0.0074792067 | AK3: =W3*$E3 -> 0.082271273 | AL3: =X3*$E3 -> 0.17629559 | AM3: =Y3*$E3 -> 0.32481126 | AN3: =Z3*$E3 -> 0.34511196 | AO3: =AA3*$E3 -> 0.93490083 | AP3: =AB3*$E3 -> 0 | ... AV3: =AH3*$E3 -> 0.73509917 | AW3: 156300 | AX3: 1492130000 | AY3: =AZ3-BE3 -> 252420000 | AZ3: 331685000 | BA3: 69227000 | BB3: 51820000 | BC3: 3513000 | BD3: 2541000 | BE3: 79265000 | BF3: 55340000 | BG3: 17215000 | BH3: 52280000 | BI3: 484000 | BJ3: 1105699000 | BK3: 951431000 | BL3: 54746000 | BM3: 34488000 | BN3: =AZ3/$AX3 -> 0.22228961 | BO3: =BA3/$AX3 -> 0.046394751 | BP3: =BB3/$AX3 -> 0.034728878 | BQ3: =BC3/$AX3 -> 0.0023543525 | BR3: =BD3/$AX3 -> 0.0017029347 | BS3: =BE3/$AX3 -> 0.053122047 | BT3: =BF3/$AX3 -> 0.037087921 | BU3: =BG3/$AX3 -> 0.011537199 | ... CA3: =BM3/$AX3 -> 0.023113268 | CB3: =BN3*$E3 -> 0.37122365 | CC3: =BO3*$E3 -> 0.077479234 | CD3: =BP3*$E3 -> 0.057997225 | CE3: =BQ3*$E3 -> 0.0039317687 | CF3: =BR3*$E3 -> 0.002843901 | CG3: =BS3*$E3 -> 0.088713819 | CH3: =BT3*$E3 -> 0.061936829 | CI3: =BU3*$E3 -> 0.019267121 | ... CO3: =CA3*$E3 -> 0.038599157
A4: 6 | B4: Active female breast cancer | C4: 228165 | D4: 0.66 | E4: 2.92 | F4: 0 | G4: 0 | H4: 0 | I4: 0 | J4: 0 | K4: 0 | L4: 0 | M4: 0 | N4: 3200 | O4: 62000 | P4: 51500 | Q4: 63200 | R4: 55200 | S4: 235300 | T4: =L4+S4 -> 235300 | U4: =F4/$T4 -> 0 | V4: =G4/$T4 -> 0 | W4: =H4/$T4 -> 0 | X4: =I4/$T4 -> 0 | Y4: =J4/$T4 -> 0 | Z4: =K4/$T4 -> 0 | AA4: =L4/$T4 -> 0 | AB4: =M4/$T4 -> 0 | ... AH4: =S4/$T4 -> 1 | AI4: =U4*$E4 -> 0 | AJ4: =V4*$E4 -> 0 | AK4: =W4*$E4 -> 0 | AL4: =X4*$E4 -> 0 | AM4: =Y4*$E4 -> 0 | AN4: =Z4*$E4 -> 0 | AO4: =AA4*$E4 -> 0 | AP4: =AB4*$E4 -> 0 | ... AV4: =AH4*$E4 -> 2.92 | AW4: 235300 | AX4: 2918957000 | AY4: =AZ4-BE4 -> 630334000 | AZ4: 1230546000 | BA4: 292903000 | BB4: 37537000 | BC4: 32650000 | BD4: 6101000 | BE4: 600212000 | BF4: 28778000 | BG4: 30401000 | BH4: 199919000 | BI4: 2046000 | BJ4: 1465224000 | BK4: 1277979000 | BL4: 223187000 | BM4: 177671000 | BN4: =AZ4/$AX4 -> 0.42157044 | BO4: =BA4/$AX4 -> 0.10034509 | BP4: =BB4/$AX4 -> 0.01285973 | BQ4: =BC4/$AX4 -> 0.011185502 | BR4: =BD4/$AX4 -> 0.0020901301 | BS4: =BE4/$AX4 -> 0.2056255 | BT4: =BF4/$AX4 -> 0.009859001 | BU4: =BG4/$AX4 -> 0.010415022 | ... CA4: =BM4/$AX4 -> 0.060867974 | CB4: =BN4*$E4 -> 1.2309857 | CC4: =BO4*$E4 -> 0.29300766 | CD4: =BP4*$E4 -> 0.037550413 | CE4: =BQ4*$E4 -> 0.032661666 | CF4: =BR4*$E4 -> 0.00610318 | CG4: =BS4*$E4 -> 0.60042647 | CH4: =BT4*$E4 -> 0.028788283 | CI4: =BU4*$E4 -> 0.030411863 | ... CO4: =CA4*$E4 -> 0.17773449
A5: 4 | B5: Active lung cancer | C5: 98603 | D5: 0.15 | E5: 2.28 | F5: 0 | G5: 200 | H5: 5500 | I5: 15500 | J5: 24500 | K5: 17100 | L5: 62800 | M5: 0 | N5: 200 | O5: 4600 | P5: 10500 | Q5: 12000 | R5: 9300 | S5: 36500 | T5: =L5+S5 -> 99300 | U5: =F5/$T5 -> 0 | V5: =G5/$T5 -> 0.0020140987 | W5: =H5/$T5 -> 0.055387714 | X5: =I5/$T5 -> 0.15609265 | Y5: =J5/$T5 -> 0.24672709 | Z5: =K5/$T5 -> 0.17220544 | AA5: =L5/$T5 -> 0.63242699 | AB5: =M5/$T5 -> 0 | ... AH5: =S5/$T5 -> 0.36757301 | AI5: =U5*$E5 -> 0 | AJ5: =V5*$E5 -> 0.004592145 | AK5: =W5*$E5 -> 0.12628399 | AL5: =X5*$E5 -> 0.35589124 | AM5: =Y5*$E5 -> 0.56253776 | AN5: =Z5*$E5 -> 0.3926284 | AO5: =AA5*$E5 -> 1.4419335 | AP5: =AB5*$E5 -> 0 | ... AV5: =AH5*$E5 -> 0.83806647 | AW5: 99300 | AX5: 2234664000 | AY5: =AZ5-BE5 -> 250132000 | AZ5: 659282000 | BA5: 92102000 | BB5: 26986000 | BC5: 5064000 | BD5: 1292000 | BE5: 409150000 | BF5: 23813000 | BG5: 14775000 | BH5: 85814000 | BI5: 284000 | BJ5: 1484498000 | BK5: 1303914000 | BL5: 90884000 | BM5: 42545000 | BN5: =AZ5/$AX5 -> 0.29502511 | BO5: =BA5/$AX5 -> 0.041215145 | BP5: =BB5/$AX5 -> 0.012076088 | BQ5: =BC5/$AX5 -> 0.0022661125 | BR5: =BD5/$AX5 -> 0.00057816298 | BS5: =BE5/$AX5 -> 0.1830924 | BT5: =BF5/$AX5 -> 0.010656188 | BU5: =BG5/$AX5 -> 0.0066117322 | ... CA5: =BM5/$AX5 -> 0.019038656 | CB5: =BN5*$E5 -> 0.67265726 | CC5: =BO5*$E5 -> 0.09397053 | CD5: =BP5*$E5 -> 0.027533482 | CE5: =BQ5*$E5 -> 0.0051667365 | CF5: =BR5*$E5 -> 0.0013182116 | CG5: =BS5*$E5 -> 0.41745068 | CH5: =BT5*$E5 -> 0.024296109 | CI5: =BU5*$E5 -> 0.015074749 | ... CO5: =CA5*$E5 -> 0.043408137
A6: 8 | B6: Active prostate cancer | C6: 220797 | D6: 0.33 | E6: 1.54 | F6: 0 | G6: 0 | H6: 4900 | I6: 32400 | J6: 86000 | K6: 105000 | L6: 228400 | M6: 0 | N6: 0 | O6: 0 | P6: 0 | Q6: 0 | R6: 0 | S6: 0 | T6: =L6+S6 -> 228400 | U6: =F6/$T6 -> 0 | V6: =G6/$T6 -> 0 | W6: =H6/$T6 -> 0.02145359 | X6: =I6/$T6 -> 0.14185639 | Y6: =J6/$T6 -> 0.3765324 | Z6: =K6/$T6 -> 0.45971979 | AA6: =L6/$T6 -> 1 | AB6: =M6/$T6 -> 0 | ... AH6: =S6/$T6 -> 0 | AI6: =U6*$E6 -> 0 | AJ6: =V6*$E6 -> 0 | AK6: =W6*$E6 -> 0.033038529 | AL6: =X6*$E6 -> 0.21845884 | AM6: =Y6*$E6 -> 0.57985989 | AN6: =Z6*$E6 -> 0.70796848 | AO6: =AA6*$E6 -> 1.54 | AP6: =AB6*$E6 -> 0 | ... AV6: =AH6*$E6 -> 0 | AW6: 228400 | AX6: 1647698000 | AY6: =AZ6-BE6 -> 463576000 | AZ6: 1061561000 | BA6: 291611000 | BB6: 23818000 | BC6: 8862000 | BD6: 4469000 | BE6: 597985000 | BF6: 17531000 | BG6: 18854000 | BH6: 97376000 | BI6: 1055000 | BJ6: 548432000 | BK6: 460379000 | BL6: 37706000 | BM6: 10822000 | BN6: =AZ6/$AX6 -> 0.64426916 | BO6: =BA6/$AX6 -> 0.17698085 | BP6: =BB6/$AX6 -> 0.014455319 | BQ6: =BC6/$AX6 -> 0.0053784128 | BR6: =BD6/$AX6 -> 0.0027122689 | BS6: =BE6/$AX6 -> 0.36292148 | BT6: =BF6/$AX6 -> 0.010639692 | BU6: =BG6/$AX6 -> 0.011442631 | ... CA6: =BM6/$AX6 -> 0.0065679512 | CB6: =BN6*$E6 -> 0.9921745 | CC6: =BO6*$E6 -> 0.27255052 | CD6: =BP6*$E6 -> 0.022261191 | CE6: =BQ6*$E6 -> 0.0082827557 | CF6: =BR6*$E6 -> 0.0041768941 | CG6: =BS6*$E6 -> 0.55889908 | CH6: =BT6*$E6 -> 0.016385126 | CI6: =BU6*$E6 -> 0.017621652 | ... CO6: =CA6*$E6 -> 0.010114645
A7: 34 | B7: Acute coronary syndrome | C7: 103648 | D7: 0.16 | E7: 1.03 | F7: 0 | G7: 600 | H7: 12900 | I7: 16500 | J7: 18500 | K7: 21100 | L7: 69600 | M7: 0 | N7: 200 | O7: 3200 | P7: 4600 | Q7: 6800 | R7: 17900 | S7: 32700 | T7: =L7+S7 -> 102300 | U7: =F7/$T7 -> 0 | V7: =G7/$T7 -> 0.0058651026 | W7: =H7/$T7 -> 0.12609971 | X7: =I7/$T7 -> 0.16129032 | Y7: =J7/$T7 -> 0.18084066 | Z7: =K7/$T7 -> 0.20625611 | AA7: =L7/$T7 -> 0.68035191 | AB7: =M7/$T7 -> 0 | ... AH7: =S7/$T7 -> 0.31964809 | AI7: =U7*$E7 -> 0 | AJ7: =V7*$E7 -> 0.0060410557 | AK7: =W7*$E7 -> 0.1298827 | AL7: =X7*$E7 -> 0.16612903 | AM7: =Y7*$E7 -> 0.18626588 | AN7: =Z7*$E7 -> 0.21244379 | AO7: =AA7*$E7 -> 0.70076246 | AP7: =AB7*$E7 -> 0 | ... AV7: =AH7*$E7 -> 0.32923754 | AW7: 102200 | AX7: 1024934000 | AY7: =AZ7-BE7 -> 69665000 | AZ7: 115580000 | BA7: 28897000 | BB7: 4220000 | BC7: 1661000 | BD7: 1792000 | BE7: 45915000 | BF7: 7038000 | BG7: 3992000 | BH7: 21804000 | BI7: 261000 | BJ7: 849991000 | BK7: 731396000 | BL7: 59364000 | BM7: 48595000 | BN7: =AZ7/$AX7 -> 0.11276824 | BO7: =BA7/$AX7 -> 0.028194011 | BP7: =BB7/$AX7 -> 0.0041173383 | BQ7: =BC7/$AX7 -> 0.0016205922 | BR7: =BD7/$AX7 -> 0.0017484053 | BS7: =BE7/$AX7 -> 0.044798007 | BT7: =BF7/$AX7 -> 0.0068667836 | BU7: =BG7/$AX7 -> 0.0038948849 | ... CA7: =BM7/$AX7 -> 0.047412809 | CB7: =BN7*$E7 -> 0.11615128 | CC7: =BO7*$E7 -> 0.029039831 | CD7: =BP7*$E7 -> 0.0042408584 | CE7: =BQ7*$E7 -> 0.0016692099 | CF7: =BR7*$E7 -> 0.0018008574 | CG7: =BS7*$E7 -> 0.046141947 | CH7: =BT7*$E7 -> 0.0070727871 | CI7: =BU7*$E7 -> 0.0040117315 | ... CO7: =CA7*$E7 -> 0.048835193
A8: 38 | B8: Acute heart failure | C8: 197856 | D8: 0.3 | E8: 1.59 | F8: 100 | G8: 300 | H8: 3700 | I8: 8300 | J8: 19600 | K8: 64900 | L8: 96900 | M8: 100 | N8: 200 | O8: 1700 | P8: 3500 | Q8: 10200 | R8: 82300 | S8: 98000 | T8: =L8+S8 -> 194900 | U8: =F8/$T8 -> 0.00051308363 | V8: =G8/$T8 -> 0.0015392509 | W8: =H8/$T8 -> 0.018984094 | X8: =I8/$T8 -> 0.042585942 | Y8: =J8/$T8 -> 0.10056439 | Z8: =K8/$T8 -> 0.33299128 | AA8: =L8/$T8 -> 0.49717804 | AB8: =M8/$T8 -> 0.00051308363 | ... AH8: =S8/$T8 -> 0.50282196 | AI8: =U8*$E8 -> 0.00081580298 | AJ8: =V8*$E8 -> 0.0024474089 | AK8: =W8*$E8 -> 0.03018471 | AL8: =X8*$E8 -> 0.067711647 | AM8: =Y8*$E8 -> 0.15989738 | AN8: =Z8*$E8 -> 0.52945613 | AO8: =AA8*$E8 -> 0.79051308 | AP8: =AB8*$E8 -> 0.00081580298 | ... AV8: =AH8*$E8 -> 0.79948692 | AW8: 194900 | AX8: 1463586000 | AY8: =AZ8-BE8 -> 311200000 | AZ8: 365695000 | BA8: 21851000 | BB8: 170091000 | BC8: 12223000 | BD8: 596000 | BE8: 54495000 | BF8: 57475000 | BG8: 11469000 | BH8: 37354000 | BI8: 140000 | BJ8: 1085342000 | BK8: 952863000 | BL8: 12549000 | BM8: 2731000 | BN8: =AZ8/$AX8 -> 0.24986232 | BO8: =BA8/$AX8 -> 0.014929768 | BP8: =BB8/$AX8 -> 0.11621524 | BQ8: =BC8/$AX8 -> 0.0083514054 | BR8: =BD8/$AX8 -> 0.00040721898 | BS8: =BE8/$AX8 -> 0.03723389 | BT8: =BF8/$AX8 -> 0.039269985 | BU8: =BG8/$AX8 -> 0.0078362324 | ... CA8: =BM8/$AX8 -> 0.0018659648 | CB8: =BN8*$E8 -> 0.3972811 | CC8: =BO8*$E8 -> 0.023738332 | CD8: =BP8*$E8 -> 0.18478223 | CE8: =BQ8*$E8 -> 0.013278735 | CF8: =BR8*$E8 -> 0.00064747818 | CG8: =BS8*$E8 -> 0.059201885 | CH8: =BT8*$E8 -> 0.062439276 | CI8: =BU8*$E8 -> 0.012459609 | ... CO8: =CA8*$E8 -> 0.0029668841
A9: 17 | B9: Addictive disorders | C9: 440883 | D9: 0.67 | E9: 1.59 | F9: 900 | G9: 146700 | H9: 422200 | I9: 226000 | J9: 128100 | K9: 45700 | L9: 969600 | M9: 600 | N9: 83000 | O9: 237400 | P9: 139800 | Q9: 78700 | R9: 31900 | S9: 571400 | T9: =L9+S9 -> 1541000 | U9: =F9/$T9 -> 0.00058403634 | V9: =G9/$T9 -> 0.095197923 | W9: =H9/$T9 -> 0.27397794 | X9: =I9/$T9 -> 0.14665801 | Y9: =J9/$T9 -> 0.083127839 | Z9: =K9/$T9 -> 0.029656067 | AA9: =L9/$T9 -> 0.62920182 | AB9: =M9/$T9 -> 0.00038935756 | ... AH9: =S9/$T9 -> 0.37079818 | AI9: =U9*$E9 -> 0.00092861778 | AJ9: =V9*$E9 -> 0.1513647 | AK9: =W9*$E9 -> 0.43562492 | AL9: =X9*$E9 -> 0.23318624 | AM9: =Y9*$E9 -> 0.13217326 | AN9: =Z9*$E9 -> 0.047153147 | AO9: =AA9*$E9 -> 1.0004309 | AP9: =AB9*$E9 -> 0.00061907852 | ... AV9: =AH9*$E9 -> 0.58956911 | AW9: 122900 | AX9: 1593144000 | AY9: =AZ9-BE9 -> 115006000 | AZ9: 132544000 | BA9: 15941000 | BB9: 24167000 | BC9: 12636000 | BD9: 9628000 | BE9: 17538000 | BF9: 11754000 | BG9: 2641000 | BH9: 37939000 | BI9: 300000 | BJ9: 1413915000 | BK9: 900579000 | BL9: 46685000 | BM9: 38421000 | BN9: =AZ9/$AX9 -> 0.083196497 | BO9: =BA9/$AX9 -> 0.010006001 | BP9: =BB9/$AX9 -> 0.015169376 | BQ9: =BC9/$AX9 -> 0.0079314864 | BR9: =BD9/$AX9 -> 0.006043396 | BS9: =BE9/$AX9 -> 0.011008421 | BT9: =BF9/$AX9 -> 0.0073778641 | BU9: =BG9/$AX9 -> 0.0016577284 | ... CA9: =BM9/$AX9 -> 0.024116464 | CB9: =BN9*$E9 -> 0.13228243 | CC9: =BO9*$E9 -> 0.015909541 | CD9: =BP9*$E9 -> 0.024119307 | CE9: =BQ9*$E9 -> 0.012611063 | CF9: =BR9*$E9 -> 0.0096089996 | CG9: =BS9*$E9 -> 0.01750339 | CH9: =BT9*$E9 -> 0.011730804 | CI9: =BU9*$E9 -> 0.0026357881 | ... CO9: =CA9*$E9 -> 0.038345178
A10: 51 | B10: Ankylosing spondylitis and related diseases | C10: 228949 | D10: 0.35 | E10: 0.94 | F10: 600 | G10: 11700 | H10: 40700 | I10: 24000 | J10: 19400 | K10: 13100 | L10: 109400 | M10: 600 | N10: 13300 | O10: 47800 | P10: 26700 | Q10: 18100 | R10: 12200 | S10: 118700 | T10: =L10+S10 -> 228100 | U10: =F10/$T10 -> 0.0026304253 | V10: =G10/$T10 -> 0.051293292 | W10: =H10/$T10 -> 0.17843051 | X10: =I10/$T10 -> 0.10521701 | Y10: =J10/$T10 -> 0.085050416 | Z10: =K10/$T10 -> 0.057430951 | AA10: =L10/$T10 -> 0.4796142 | AB10: =M10/$T10 -> 0.0026304253 | ... AH10: =S10/$T10 -> 0.5203858 | AI10: =U10*$E10 -> 0.0024725997 | AJ10: =V10*$E10 -> 0.048215695 | AK10: =W10*$E10 -> 0.16772468 | AL10: =X10*$E10 -> 0.098903989 | AM10: =Y10*$E10 -> 0.079947391 | AN10: =Z10*$E10 -> 0.053985094 | AO10: =AA10*$E10 -> 0.45083735 | AP10: =AB10*$E10 -> 0.0024725997 | ... AV10: =AH10*$E10 -> 0.48916265 | AW10: 715300 | AX10: 1779924000 | AY10: =AZ10-BE10 -> 200676000 | AZ10: 329600000 | BA10: 76133000 | BB10: 26493000 | BC10: 13691000 | BD10: 21706000 | BE10: 128924000 | BF10: 26624000 | BG10: 10599000 | BH10: 24874000 | BI10: 554000 | BJ10: 1063991000 | BK10: 230483000 | BL10: 386334000 | BM10: 222060000 | BN10: =AZ10/$AX10 -> 0.18517645 | BO10: =BA10/$AX10 -> 0.042773175 | BP10: =BB10/$AX10 -> 0.014884343 | BQ10: =BC10/$AX10 -> 0.0076919015 | BR10: =BD10/$AX10 -> 0.012194903 | BS10: =BE10/$AX10 -> 0.072432306 | BT10: =BF10/$AX10 -> 0.014957942 | BU10: =BG10/$AX10 -> 0.0059547486 | ... CA10: =BM10/$AX10 -> 0.12475814 | CB10: =BN10*$E10 -> 0.17406586 | CC10: =BO10*$E10 -> 0.040206784 | CD10: =BP10*$E10 -> 0.013991283 | CE10: =BQ10*$E10 -> 0.0072303874 | CF10: =BR10*$E10 -> 0.011463209 | CG10: =BS10*$E10 -> 0.068086368 | CH10: =BT10*$E10 -> 0.014060466 | CI10: =BU10*$E10 -> 0.0055974637 | ... CO10: =CA10*$E10 -> 0.11727265
A11: 20 | B11: Antidepressant or mood-regulating treatments | C11: 2994072 | D11: 4.5 | E11: 2.88 | F11: 29900 | G11: 414900 | H11: 1429300 | I11: 986400 | J11: 897800 | K11: 1074300 | L11: 4832700 | M11: 14400 | N11: 640800 | O11: 2491900 | P11: 1829300 | Q11: 1783100 | R11: 2776500 | S11: 9536200 | T11: =L11+S11 -> 14368900 | U11: =F11/$T11 -> 0.002080883 | V11: =G11/$T11 -> 0.028874862 | W11: =H11/$T11 -> 0.099471776 | X11: =I11/$T11 -> 0.068648261 | Y11: =J11/$T11 -> 0.062482166 | Z11: =K11/$T11 -> 0.07476564 | AA11: =L11/$T11 -> 0.33633055 | AB11: =M11/$T11 -> 0.0010021644 | ... AH11: =S11/$T11 -> 0.66366945 | AI11: =U11*$E11 -> 0.0059929431 | AJ11: =V11*$E11 -> 0.083159602 | AK11: =W11*$E11 -> 0.28647871 | AL11: =X11*$E11 -> 0.19770699 | AM11: =Y11*$E11 -> 0.17994864 | AN11: =Z11*$E11 -> 0.21532504 | AO11: =AA11*$E11 -> 0.96863198 | AP11: =AB11*$E11 -> 0.0028862335 | ... AV11: =AH11*$E11 -> 1.911368 | AW11: 228100 | AX11: 937950000 | AY11: =AZ11-BE11 -> 123755000 | AZ11: 604595000 | BA11: 43238000 | BB11: 5449000 | BC11: 31633000 | BD11: 7322000 | BE11: 480840000 | BF11: 9710000 | BG11: 12685000 | BH11: 10355000 | BI11: 3363000 | BJ11: 146441000 | BK11: 108527000 | BL11: 186914000 | BM11: 57647000 | BN11: =AZ11/$AX11 -> 0.64459193 | BO11: =BA11/$AX11 -> 0.046098406 | BP11: =BB11/$AX11 -> 0.0058094781 | BQ11: =BC11/$AX11 -> 0.033725678 | BR11: =BD11/$AX11 -> 0.0078063863 | BS11: =BE11/$AX11 -> 0.51264993 | BT11: =BF11/$AX11 -> 0.010352364 | BU11: =BG11/$AX11 -> 0.013524175 | ... CA11: =BM11/$AX11 -> 0.061460632 | CB11: =BN11*$E11 -> 1.8564248 | CC11: =BO11*$E11 -> 0.13276341 | CD11: =BP11*$E11 -> 0.016731297 | CE11: =BQ11*$E11 -> 0.097129954 | CF11: =BR11*$E11 -> 0.022482392 | CG11: =BS11*$E11 -> 1.4764318 | CH11: =BT11*$E11 -> 0.029814809 | CI11: =BU11*$E11 -> 0.038949624 | ... CO11: =CA11*$E11 -> 0.17700662
A12: 33 | B12: Antihypertensive treatments | C12: 7329506 | D12: 11 | E12: 4.26 | F12: 9700 | G12: 158800 | H12: 2307000 | I12: 3693700 | J12: 4827200 | K12: 4381900 | L12: 15378300 | M12: 7200 | N12: 200500 | O12: 2249700 | P12: 3414000 | Q12: 4975900 | R12: 6972800 | S12: 17820400 | T12: =L12+S12 -> 33198700 | U12: =F12/$T12 -> 0.00029218012 | V12: =G12/$T12 -> 0.0047833198 | W12: =H12/$T12 -> 0.069490673 | X12: =I12/$T12 -> 0.11126038 | Y12: =J12/$T12 -> 0.14540328 | Z12: =K12/$T12 -> 0.13199011 | AA12: =L12/$T12 -> 0.46321995 | AB12: =M12/$T12 -> 0.00021687596 | ... AH12: =S12/$T12 -> 0.53678005 | AI12: =U12*$E12 -> 0.0012446873 | AJ12: =V12*$E12 -> 0.020376942 | AK12: =W12*$E12 -> 0.29603027 | AL12: =X12*$E12 -> 0.47396922 | AM12: =Y12*$E12 -> 0.61941799 | AN12: =Z12*$E12 -> 0.56227786 | AO12: =AA12*$E12 -> 1.973317 | AP12: =AB12*$E12 -> 0.0009238916 | ... AV12: =AH12*$E12 -> 2.286683 | AW12: 2924800 | AX12: 2849266000 | AY12: =AZ12-BE12 -> 855711000 | AZ12: 1183330000 | BA12: 432429000 | BB12: 50788000 | BC12: 120653000 | BD12: 80691000 | BE12: 327619000 | BF12: 94948000 | BG12: 49994000 | BH12: 15616000 | BI12: 10590000 | BJ12: 225305000 | BK12: 13433000 | BL12: 1440632000 | BM12: 935320000 | BN12: =AZ12/$AX12 -> 0.41531047 | BO12: =BA12/$AX12 -> 0.15176856 | BP12: =BB12/$AX12 -> 0.017824942 | BQ12: =BC12/$AX12 -> 0.042345292 | BR12: =BD12/$AX12 -> 0.028319925 | BS12: =BE12/$AX12 -> 0.11498365 | BT12: =BF12/$AX12 -> 0.03332367 | BU12: =BG12/$AX12 -> 0.017546273 | ... CA12: =BM12/$AX12 -> 0.328267 | CB12: =BN12*$E12 -> 1.7692226 | CC12: =BO12*$E12 -> 0.64653407 | CD12: =BP12*$E12 -> 0.075934251 | CE12: =BQ12*$E12 -> 0.18039094 | CF12: =BR12*$E12 -> 0.12064288 | CG12: =BS12*$E12 -> 0.48983034 | CH12: =BT12*$E12 -> 0.14195883 | CI12: =BU12*$E12 -> 0.074747124 | ... CO12: =CA12*$E12 -> 1.3984174
